[2023-10-01 16:20:01,955] {taskinstance.py:851} INFO - Dependencies all met for <TaskInstance: backup_postgres.perform_postgresql_backup 2023-10-01T16:09:18.581743+00:00 [queued]>
[2023-10-01 16:20:02,001] {taskinstance.py:851} INFO - Dependencies all met for <TaskInstance: backup_postgres.perform_postgresql_backup 2023-10-01T16:09:18.581743+00:00 [queued]>
[2023-10-01 16:20:02,006] {taskinstance.py:1042} INFO - 
--------------------------------------------------------------------------------
[2023-10-01 16:20:02,009] {taskinstance.py:1043} INFO - Starting attempt 6 of 6
[2023-10-01 16:20:02,013] {taskinstance.py:1044} INFO - 
--------------------------------------------------------------------------------
[2023-10-01 16:20:02,051] {taskinstance.py:1063} INFO - Executing <Task(BashOperator): perform_postgresql_backup> on 2023-10-01T16:09:18.581743+00:00
[2023-10-01 16:20:02,060] {standard_task_runner.py:52} INFO - Started process 11740 to run task
[2023-10-01 16:20:02,080] {standard_task_runner.py:76} INFO - Running: ['airflow', 'tasks', 'run', 'backup_postgres', 'perform_postgresql_backup', '2023-10-01T16:09:18.581743+00:00', '--job-id', '46', '--pool', 'default_pool', '--raw', '--subdir', 'DAGS_FOLDER/backup_postgres.py', '--cfg-path', '/tmp/tmphkh82la5', '--error-file', '/tmp/tmpre7wlz6w']
[2023-10-01 16:20:02,087] {standard_task_runner.py:77} INFO - Job 46: Subtask perform_postgresql_backup
[2023-10-01 16:20:02,195] {logging_mixin.py:104} INFO - Running <TaskInstance: backup_postgres.perform_postgresql_backup 2023-10-01T16:09:18.581743+00:00 [running]> on host 55885b568803
[2023-10-01 16:20:02,301] {taskinstance.py:1257} INFO - Exporting the following env vars:
AIRFLOW_CTX_DAG_OWNER=svastikkka
AIRFLOW_CTX_DAG_ID=backup_postgres
AIRFLOW_CTX_TASK_ID=perform_postgresql_backup
AIRFLOW_CTX_EXECUTION_DATE=2023-10-01T16:09:18.581743+00:00
AIRFLOW_CTX_DAG_RUN_ID=manual__2023-10-01T16:09:18.581743+00:00
[2023-10-01 16:20:02,312] {bash.py:135} INFO - Tmp dir root location: 
 /tmp
[2023-10-01 16:20:02,347] {bash.py:158} INFO - Running command: docker run --rm postgres:13 pg_dump -U airflow -h {conn_params['host']} -d airflow -f /tmp/backup.sql
[2023-10-01 16:20:02,394] {bash.py:169} INFO - Output:
[2023-10-01 16:20:02,398] {bash.py:173} INFO - bash: docker: command not found
[2023-10-01 16:20:02,402] {bash.py:177} INFO - Command exited with return code 127
[2023-10-01 16:20:02,430] {taskinstance.py:1455} ERROR - Bash command failed. The command returned a non-zero exit code.
Traceback (most recent call last):
  File "/home/airflow/.local/lib/python3.6/site-packages/airflow/models/taskinstance.py", line 1112, in _run_raw_task
    self._prepare_and_execute_task_with_callbacks(context, task)
  File "/home/airflow/.local/lib/python3.6/site-packages/airflow/models/taskinstance.py", line 1285, in _prepare_and_execute_task_with_callbacks
    result = self._execute_task(context, task_copy)
  File "/home/airflow/.local/lib/python3.6/site-packages/airflow/models/taskinstance.py", line 1315, in _execute_task
    result = task_copy.execute(context=context)
  File "/home/airflow/.local/lib/python3.6/site-packages/airflow/operators/bash.py", line 180, in execute
    raise AirflowException('Bash command failed. The command returned a non-zero exit code.')
airflow.exceptions.AirflowException: Bash command failed. The command returned a non-zero exit code.
[2023-10-01 16:20:02,440] {taskinstance.py:1503} INFO - Marking task as FAILED. dag_id=backup_postgres, task_id=perform_postgresql_backup, execution_date=20231001T160918, start_date=20231001T162001, end_date=20231001T162002
[2023-10-01 16:20:02,548] {local_task_job.py:146} INFO - Task exited with return code 1
