[2023-10-01 10:00:20,998] {taskinstance.py:851} INFO - Dependencies all met for <TaskInstance: postgres_v1.insert_into_table 2021-09-03T00:00:00+00:00 [queued]>
[2023-10-01 10:00:21,077] {taskinstance.py:851} INFO - Dependencies all met for <TaskInstance: postgres_v1.insert_into_table 2021-09-03T00:00:00+00:00 [queued]>
[2023-10-01 10:00:21,080] {taskinstance.py:1042} INFO - 
--------------------------------------------------------------------------------
[2023-10-01 10:00:21,081] {taskinstance.py:1043} INFO - Starting attempt 1 of 6
[2023-10-01 10:00:21,083] {taskinstance.py:1044} INFO - 
--------------------------------------------------------------------------------
[2023-10-01 10:00:21,130] {taskinstance.py:1063} INFO - Executing <Task(PostgresOperator): insert_into_table> on 2021-09-03T00:00:00+00:00
[2023-10-01 10:00:21,147] {standard_task_runner.py:52} INFO - Started process 44260 to run task
[2023-10-01 10:00:21,170] {standard_task_runner.py:76} INFO - Running: ['airflow', 'tasks', 'run', 'postgres_v1', 'insert_into_table', '2021-09-03T00:00:00+00:00', '--job-id', '2637', '--pool', 'default_pool', '--raw', '--subdir', 'DAGS_FOLDER/1_postgresql.py', '--cfg-path', '/tmp/tmpphuo6q2i', '--error-file', '/tmp/tmprgz2za6q']
[2023-10-01 10:00:21,178] {standard_task_runner.py:77} INFO - Job 2637: Subtask insert_into_table
[2023-10-01 10:00:21,434] {logging_mixin.py:104} INFO - Running <TaskInstance: postgres_v1.insert_into_table 2021-09-03T00:00:00+00:00 [running]> on host d4ed655215d1
[2023-10-01 10:00:21,722] {taskinstance.py:1257} INFO - Exporting the following env vars:
AIRFLOW_CTX_DAG_OWNER=svastikkka
AIRFLOW_CTX_DAG_ID=postgres_v1
AIRFLOW_CTX_TASK_ID=insert_into_table
AIRFLOW_CTX_EXECUTION_DATE=2021-09-03T00:00:00+00:00
AIRFLOW_CTX_DAG_RUN_ID=scheduled__2021-09-03T00:00:00+00:00
[2023-10-01 10:00:21,726] {postgres.py:69} INFO - Executing: 
            insert into dag_runs (dt, dag_id) values ('2021-09-03', 'postgres_v1')
        
[2023-10-01 10:00:21,814] {taskinstance.py:1455} ERROR - The conn_id `postgres_localhost` isn't defined
Traceback (most recent call last):
  File "/home/airflow/.local/lib/python3.6/site-packages/airflow/models/taskinstance.py", line 1112, in _run_raw_task
    self._prepare_and_execute_task_with_callbacks(context, task)
  File "/home/airflow/.local/lib/python3.6/site-packages/airflow/models/taskinstance.py", line 1285, in _prepare_and_execute_task_with_callbacks
    result = self._execute_task(context, task_copy)
  File "/home/airflow/.local/lib/python3.6/site-packages/airflow/models/taskinstance.py", line 1315, in _execute_task
    result = task_copy.execute(context=context)
  File "/home/airflow/.local/lib/python3.6/site-packages/airflow/providers/postgres/operators/postgres.py", line 71, in execute
    self.hook.run(self.sql, self.autocommit, parameters=self.parameters)
  File "/home/airflow/.local/lib/python3.6/site-packages/airflow/hooks/dbapi.py", line 173, in run
    with closing(self.get_conn()) as conn:
  File "/home/airflow/.local/lib/python3.6/site-packages/airflow/providers/postgres/hooks/postgres.py", line 83, in get_conn
    conn = self.connection or self.get_connection(conn_id)
  File "/home/airflow/.local/lib/python3.6/site-packages/airflow/hooks/base.py", line 63, in get_connection
    conn = Connection.get_connection_from_secrets(conn_id)
  File "/home/airflow/.local/lib/python3.6/site-packages/airflow/models/connection.py", line 354, in get_connection_from_secrets
    raise AirflowNotFoundException(f"The conn_id `{conn_id}` isn't defined")
airflow.exceptions.AirflowNotFoundException: The conn_id `postgres_localhost` isn't defined
[2023-10-01 10:00:21,829] {taskinstance.py:1503} INFO - Marking task as UP_FOR_RETRY. dag_id=postgres_v1, task_id=insert_into_table, execution_date=20210903T000000, start_date=20231001T100021, end_date=20231001T100021
[2023-10-01 10:00:22,042] {local_task_job.py:146} INFO - Task exited with return code 1
